Workbook

Sheet Summary
A1: Nuwara Eliya landslide data - summary
A2: Source: NBRI package (NBRI-GEO-PKG-2026), cleaned by preprocess_nbri.py. Counts below are live formulas on the other sheets.
A4: Incidents by type | B4: Count
A5: Cutting failure (CF) | B5: =COUNTIF(Incidents!$B$2:$B$1200,"CF") -> 940
A6: Landslide (L) | B6: =COUNTIF(Incidents!$B$2:$B$1200,"L") -> 81
A7: Rock fall (RF) | B7: =COUNTIF(Incidents!$B$2:$B$1200,"RF") -> 80
A8: Slope failure (SF) | B8: =COUNTIF(Incidents!$B$2:$B$1200,"SF") -> 55
A9: Ground subsidence (GS) | B9: =COUNTIF(Incidents!$B$2:$B$1200,"GS") -> 29
A10: Other (OTHER) | B10: =COUNTIF(Incidents!$B$2:$B$1200,"OTHER") -> 14
A11: Total | B11: =SUM(B5:B10) -> 1199
A12: In 3 target DS divisions | B12: =COUNTIF(Incidents!$O$2:$O$1200,TRUE()) -> 731
A13: With valid occurrence date | B13: =COUNTIF(Incidents!$J$2:$J$1200,TRUE()) -> 147
A15: Samples | B15: Count
A16: Positives (label = 1) | B16: =COUNTIF(Samples!$E$2:$E$5865,1) -> 1466
A17: Negatives (label = 0) | B17: =COUNTIF(Samples!$E$2:$E$5865,0) -> 4398
A18: Negatives per positive | B18: =IFERROR(B17/B16,0) -> 3
A19: Fold 0 - positives | B19: =COUNTIFS(Samples!$H$2:$H$5865,0,Samples!$E$2:$E$5865,1) -> 241
A20: Fold 1 - positives | B20: =COUNTIFS(Samples!$H$2:$H$5865,1,Samples!$E$2:$E$5865,1) -> 425
A21: Fold 2 - positives | B21: =COUNTIFS(Samples!$H$2:$H$5865,2,Samples!$E$2:$E$5865,1) -> 185
A22: Fold 3 - positives | B22: =COUNTIFS(Samples!$H$2:$H$5865,3,Samples!$E$2:$E$5865,1) -> 174
A23: Fold 4 - positives | B23: =COUNTIFS(Samples!$H$2:$H$5865,4,Samples!$E$2:$E$5865,1) -> 441
A25: Notes
A26: Rain_1h / Rain_24h / Rain_Cum columns on the Incidents sheet are empty in the NBRI source data (only "-").
A27: occ_date is the incident date; report_date is when it was filed (median lag ~26 days).
A28: Samples: negatives are random points >= 500 m from any landslide; fold = 3 km spatial block.
A29: lhmp_benchmark_class is the NBRI hazard class - use as a benchmark, not a model feature.
A30: Rain_Stations: Dept. of Meteorology station locations from the team repo (locations only, no rainfall values).
A31: Coordinates are WGS84 (lat/lon).

Sheet Incidents
A1: Case_ID | B1: Type_Code | C1: Inc_Type | D1: failure_group | E1: DS_Name | F1: GND_Name | G1: Village | H1: report_date | I1: occ_date | J1: has_occ_date | K1: Cause | L1: Rain_1h | M1: Rain_24h | N1: Rain_Cum | O1: in_study_area | P1: location_id | Q1: lon | R1: lat
A2: NWE150014 | B2: CF | C2: Cutting Failure | D2: cutting | E2: Hanguranketha | F2: Muloya | G2: මුල්ඔය වතුයාය, පහල කොටස | H2: 42137 | J2: =FALSE() -> FALSE | O2: =FALSE() -> FALSE | P2: 0 | Q2: 80.756045 | R2: 7.098072
A3: NWE150052 | B3: CF | C3: Cutting Failure | D3: cutting | E3: Hanguranketha | F3: Hope | G3: හෝප් වත්ත, කර්මාන්ත ශාලා කොටස | H3: 42025 | J3: =FALSE() -> FALSE | O3: =FALSE() -> FALSE | P3: 1 | Q3: 80.746482 | R3: 7.109057
A4: NWE160006 | B4: CF | C4: Cutting Failure | D4: cutting | E4: Hanguranketha | F4: Muloya | G4: මුල්ඔය වතුයායේ, පහළ කොටසේ ලයින් අංක 01 හා 02 | H4: 42522 | J4: =FALSE() -> FALSE | O4: =FALSE() -> FALSE | P4: 2 | Q4: 80.755744 | R4: 7.099661
A5: NWE160007 | B5: CF | C5: Cutting Failure | D5: cutting | E5: Hanguranketha | F5: Muloya | G5: මුල්ඔය වතුයායේ, පහළ කොටසේ ලයින් අංක 17 | H5: 42522 | J5: =FALSE() -> FALSE | O5: =FALSE() -> FALSE | P5: 3 | Q5: 80.753045 | R5: 7.098072
A6: NWE160034 | B6: CF | C6: Cutting Failure | D6: cutting | E6: Hanguranketha | F6: Dodamkumbura | G6: දොඩම්කුඹුර, රිකිල්ලගස්කඩ | H6: 42704 | J6: =FALSE() -> FALSE | O6: =FALSE() -> FALSE | P6: 4 | Q6: 80.790857 | R6: 7.151016
A7: NWE160038 | B7: CF | C7: Cutting Failure | D7: cutting | E7: Nuwara Eliya | F7: Toppass | G7: ශාන්තිපුර | H7: 42604 | J7: =FALSE() -> FALSE | O7: =FALSE() -> FALSE | P7: 5 | Q7: 80.749854 | R7: 6.977065
A8: NWE160039 | B8: CF | C8: Cutting Failure | D8: cutting | E8: Nuwara Eliya | F8: Lippakelle | G8: ලිපකැලේ ප්‍රාථමික විදුහල ආසල | H8: 42495 | J8: =FALSE() -> FALSE | O8: =FALSE() -> FALSE | P8: 6 | Q8: 80.722544 | R8: 6.890737
A9: NWE160040 | B9: CF | C9: Cutting Failure | D9: cutting | E9: Nuwara Eliya | F9: Toppass | G9: ටොප් පාස් ග්‍රාම නිලධාරී කාර්යාලය සහ බුදු මැදුර ආශ්‍රිත භූමියේ | H9: 42604 | J9: =FALSE() -> FALSE | O9: =FALSE() -> FALSE | P9: 7 | Q9: 80.748217 | R9: 6.993532
A10: NWE160044 | B10: CF | C10: Cutting Failure | D10: cutting | E10: Walapane | F10: Palalpathana | G10: ලීඩ්ස්ඩෙල් වතුයායේ දියණිල්ල ඉහළ කොටසේ ක්ෂේත්‍ර අංක 6ට | H10: 42510 | J10: =FALSE() -> FALSE | O10: =TRUE() -> TRUE | P10: 8 | Q10: 80.8663 | R10: 7.03809
A11: NWE160053 | B11: CF | C11: Cutting Failure | D11: cutting | E11: Hanguranketha | F11: Muloya | G11: මුල් ඔය වතුයාය පහල කොටස ලයින් අංක 01 හා 02 ආශ්‍රිතව | H11: 42514 | J11: =FALSE() -> FALSE | O11: =FALSE() -> FALSE | P11: 2 | Q11: 80.755744 | R11: 7.099661
A12: NWE160055 | B12: CF | C12: Cutting Failure | D12: cutting | E12: Nuwara Eliya | F12: Lippakelle | G12: ලිපකැලේ ප්‍රාථමික විදුහල ආසන්නයේ සුරේෂ් කුමාර් යන නිවස | H12: 42516 | J12: =FALSE() -> FALSE | O12: =FALSE() -> FALSE | P12: 6 | Q12: 80.722544 | R12: 6.890737
A13: NWE160061 | B13: CF | C13: Cutting Failure | D13: cutting | E13: Nuwara Eliya | F13: Lippakelle | G13: කොට්ඨාසයේ ලිපකැලේ වතුයායේ (Lipakelle Estate) අංක 03 කොටසේ (No 03 Division) ලයින් කාමර10 | H13: 42509 | J13: =FALSE() -> FALSE | O13: =FALSE() -> FALSE | P13: 9 | Q13: 80.736845 | R13: 6.889524
A14: NWE160062 | B14: CF | C14: Cutting Failure | D14: cutting | E14: Nuwara Eliya | F14: Lippakelle | G14: ලිපකැලේ වතුයායේ (Lipakelle Estate) ලිපකැලේ කොටසේ (Lipakelle Division) වෛද්‍ය නිල නිවාසය අසල | H14: 42509 | J14: =FALSE() -> FALSE | O14: =FALSE() -> FALSE | P14: 10 | Q14: 80.724452 | R14: 6.895791
A15: NWE160149 | B15: CF | C15: Cutting Failure | D15: cutting | E15: Nuwara Eliya | F15: Toppass | G15: ටොප් පාස් ග්‍රාම නිලධාරී කාර්යාලය සහ බුදු මැදුර ආශ්‍රිත භූමිය | H15: 42655 | J15: =FALSE() -> FALSE | O15: =FALSE() -> FALSE | P15: 7 | Q15: 80.748217 | R15: 6.993532
A16: NWE160200 | B16: CF | C16: Cutting Failure | D16: cutting | E16: Kothmale | F16: Ramboda | G16: බ්ලුෆීල්ඩ් වතුයාය, බ්ලුෆීල්ඩ් කොටස | H16: 42542 | J16: =FALSE() -> FALSE | O16: =TRUE() -> TRUE | P16: 11 | Q16: 80.682458 | R16: 7.03055
A17: NWE170005 | B17: CF | C17: Cutting Failure | D17: cutting | E17: Hanguranketha | F17: Deniyagama | G17: දෙනියගම, දෙහිපේ | H17: 42795 | J17: =FALSE() -> FALSE | O17: =FALSE() -> FALSE | P17: 12 | Q17: 80.791955 | R17: 7.116142
A18: NWE170009 | B18: CF | C18: Cutting Failure | D18: cutting | E18: Kothmale | F18: Karagahayatathenna | G18: කරගහයටතැන්න, දුණුකේදෙණිය | H18: 42876 | J18: =FALSE() -> FALSE | O18: =TRUE() -> TRUE | P18: 13 | Q18: 80.642789 | R18: 7.001066
A19: NWE170024 | B19: CF | C19: Cutting Failure | D19: cutting | E19: Hanguranketha | F19: Udagama | G19: උඩගම, බතලවත්ත | H19: 42816 | J19: =FALSE() -> FALSE | O19: =FALSE() -> FALSE | P19: 14 | Q19: 80.803366 | R19: 7.070319
A20: NWE170027 | B20: CF | C20: Cutting Failure | D20: cutting | E20: Nuwara Eliya | F20: Toppass | G20: වෙස්ට්වර්ඩ්හෝ වතුයායේ පේළි කාමර 08 ආශ්‍රිතව | H20: 42969 | J20: =FALSE() -> FALSE | O20: =FALSE() -> FALSE | P20: 15 | Q20: 80.743909 | R20: 7.000015
A21: NWE170028 | B21: CF | C21: Cutting Failure | D21: cutting | E21: Nuwara Eliya | F21: Windicorner | G21: අංක 61, ධර්මපාලපුර, රැවන්එළිය, නුවරඑළිය | H21: 43005 | J21: =FALSE() -> FALSE | O21: =FALSE() -> FALSE | P21: 16 | Q21: 80.772136 | R21: 6.942648
A22: NWE170035 | B22: CF | C22: Cutting Failure | D22: cutting | E22: Nuwara Eliya | F22: Nuwara Eliya Central | G22: මහින්ද මාවත, හාවාඑළිය, නුවරඑළිය | H22: 43072 | J22: =FALSE() -> FALSE | O22: =FALSE() -> FALSE | P22: 17 | Q22: 80.783696 | R22: 6.967873
A23: NWE170037 | B23: CF | C23: Cutting Failure | D23: cutting | E23: Nuwara Eliya | F23: Seethaeliya | G23: පොල්ගහ වංගුව | H23: 43070 | J23: =FALSE() -> FALSE | O23: =FALSE() -> FALSE | P23: 18 | Q23: 80.800615 | R23: 6.93816
A24: NWE170044 | B24: CF | C24: Cutting Failure | D24: cutting | E24: Nuwara Eliya | F24: Kandapola | G24: මහින්ද මාවත, හාවාඑළිය, නුවරඑළිය | H24: 43073 | J24: =FALSE() -> FALSE | O24: =FALSE() -> FALSE | P24: 17 | Q24: 80.783696 | R24: 6.967873
A25: NWE170052 | B25: CF | C25: Cutting Failure | D25: cutting | E25: Nuwara Eliya | F25: Toppass | G25: වෙස්ට්වර්ඩ්හෝ වතුයායේ පේළි කාමර 08 | H25: 42982 | J25: =FALSE() -> FALSE | O25: =FALSE() -> FALSE | P25: 15 | Q25: 80.743909 | R25: 7.000015
A26: NWE170057 | B26: CF | C26: Cutting Failure | D26: cutting | E26: Nuwara Eliya | F26: Windicorner | G26: අංක 61, ධර්මපාලපුර, රැවන්එළිය, නුවරඑළිය | H26: 42885 | J26: =FALSE() -> FALSE | O26: =FALSE() -> FALSE | P26: 16 | Q26: 80.772136 | R26: 6.942648
A27: NWE170062 | B27: CF | C27: Cutting Failure | D27: cutting | E27: Nuwara Eliya | F27: Seethaeliya | G27: පොල්ගහ වංගුව | H27: 43069 | J27: =FALSE() -> FALSE | O27: =FALSE() -> FALSE | P27: 18 | Q27: 80.800615 | R27: 6.93816
A28: NWE170063 | B28: CF | C28: Cutting Failure | D28: cutting | E28: Nuwara Eliya | F28: Kandapola | G28: කොට්ලෝජ් වත්ත, පෝස්ට්වුඩ් කොටසේ, ක්ෂේත්‍ර අංක 17 (ලයින් කාමර අංක 06) | H28: 42999 | J28: =FALSE() -> FALSE | O28: =FALSE() -> FALSE | P28: 19 | Q28: 80.818193 | R28: 6.993731
A29: NWE170065 | B29: CF | C29: Cutting Failure | D29: cutting | E29: Hanguranketha | F29: Elamulla | G29: එළමුල්ල | H29: 42795 | J29: =FALSE() -> FALSE | O29: =FALSE() -> FALSE | P29: 20 | Q29: 80.77917 | R29: 7.082207
A30: NWE170209 | B30: CF | C30: Cutting Failure | D30: cutting | E30: Nuwara Eliya | F30: Summerset | G30: ලයින්ඩේල් වතුයායේ පහළ කොටස | H30: 42958 | J30: =FALSE() -> FALSE | O30: =FALSE() -> FALSE | P30: 21 | Q30: 80.715098 | R30: 6.932981
A31: NWE170211 | B31: CF | C31: Cutting Failure | D31: cutting | E31: Nuwara Eliya | F31: Perakumpura | G31: පැරකුම්පුර ජනපදය, අලුත් කොලණිය, | H31: 42999 | J31: =FALSE() -> FALSE | O31: =FALSE() -> FALSE | P31: 22 | Q31: 80.750308 | R31: 6.914744
A32: NWE170256 | B32: CF | C32: Cutting Failure | D32: cutting | E32: Kothmale | F32: Ruwanpura | G32: අංක 18, ඉහළ ඩොන්සයිඩ්, රුවන්පුර, හපුගස්තලාව | H32: 43067 | J32: =FALSE() -> FALSE | O32: =TRUE() -> TRUE | P32: 23 | Q32: 80.560919 | R32: 7.058037
A33: NWE170260 | B33: CF | C33: Cutting Failure | D33: cutting | E33: Kothmale | F33: Katarandana | G33: නුගතොට | H33: 43038 | J33: =FALSE() -> FALSE | O33: =TRUE() -> TRUE | P33: 24 | Q33: 80.649056 | R33: 7.033162
A34: NWE180010 | B34: CF | C34: Cutting Failure | D34: cutting | E34: Hanguranketha | F34: Bambaragama West | G34: දෙල්පත්කඩ, පල්ලේබෝවල | H34: 43398 | J34: =FALSE() -> FALSE | O34: =FALSE() -> FALSE | P34: 25 | Q34: 80.732706 | R34: 7.137123
A35: NWE180011 | B35: CF | C35: Cutting Failure | D35: cutting | E35: Hanguranketha | F35: Bambaragama West | G35: දෙල්පත්කඩ, පල්ලේබෝවල | H35: 43398 | J35: =FALSE() -> FALSE | O35: =FALSE() -> FALSE | P35: 26 | Q35: 80.731908 | R35: 7.137641
A36: NWE180012 | B36: CF | C36: Cutting Failure | D36: cutting | E36: Hanguranketha | F36: Bambaragama West | G36: දෙල්පත්කඩ, පල්ලේබෝවල | H36: 43398 | J36: =FALSE() -> FALSE | O36: =FALSE() -> FALSE | P36: 27 | Q36: 80.732505 | R36: 7.137164
A37: NWE180014 | B37: CF | C37: Cutting Failure | D37: cutting | E37: Hanguranketha | F37: Malanwatta | G37: ගන්නෑව, උඩගම | H37: 43398 | J37: =FALSE() -> FALSE | O37: =FALSE() -> FALSE | P37: 28 | Q37: 80.727917 | R37: 7.147669
A38: NWE180015 | B38: CF | C38: Cutting Failure | D38: cutting | E38: Hanguranketha | F38: Kawatayamana | G38: කවටයාමාන, හේවාහැට | H38: 43209 | J38: =FALSE() -> FALSE | O38: =FALSE() -> FALSE | P38: 29 | Q38: 80.778504 | R38: 7.112744
A39: NWE180019 | B39: CF | C39: Cutting Failure | D39: cutting | E39: Hanguranketha | F39: Uda Padiyapelella | G39: නුගයාය, පදියපැලැල්ල | H39: 43350 | J39: =FALSE() -> FALSE | O39: =FALSE() -> FALSE | P39: 30 | Q39: 80.795727 | R39: 7.089283
A40: NWE180021 | B40: CF | C40: Cutting Failure | D40: cutting | E40: Hanguranketha | F40: Dodamkumbura | G40: දොඩම්කුඹුර, රිකිල්ලගස්කඩ | H40: 43250 | J40: =FALSE() -> FALSE | O40: =FALSE() -> FALSE | P40: 31 | Q40: 80.791008 | R40: 7.156319
...

Sheet Samples
A1: failure_group | B1: occ_date | C1: in_study_area | D1: source | E1: label | F1: lhmp_benchmark_class | G1: block_id | H1: fold | I1: sample_id | J1: lat | K1: lon
A2: cutting | C2: =FALSE() -> FALSE | D2: incident_cutting | E2: 1 | F2: 2 | G2: 66_70 | H2: 4 | I2: 0 | J2: 7.098072 | K2: 80.756045
A3: cutting | C3: =FALSE() -> FALSE | D3: incident_cutting | E3: 1 | F3: 3 | G3: 65_70 | H3: 4 | I3: 1 | J3: 7.109057 | K3: 80.746482
A4: cutting | C4: =FALSE() -> FALSE | D4: incident_cutting | E4: 1 | F4: 2 | G4: 66_70 | H4: 4 | I4: 2 | J4: 7.099661 | K4: 80.755744
A5: cutting | C5: =FALSE() -> FALSE | D5: incident_cutting | E5: 1 | F5: 2 | G5: 65_70 | H5: 4 | I5: 3 | J5: 7.098072 | K5: 80.753045
A6: cutting | C6: =FALSE() -> FALSE | D6: incident_cutting | E6: 1 | F6: 1 | G6: 67_72 | H6: 3 | I6: 4 | J6: 7.1510155 | K6: 80.790857
A7: cutting | C7: =FALSE() -> FALSE | D7: incident_cutting | E7: 1 | F7: 2 | G7: 65_65 | H7: 4 | I7: 5 | J7: 6.977065 | K7: 80.749854
A8: cutting | C8: =FALSE() -> FALSE | D8: incident_cutting | E8: 1 | F8: 1 | G8: 64_62 | H8: 2 | I8: 6 | J8: 6.890737 | K8: 80.722544
A9: cutting | C9: =FALSE() -> FALSE | D9: incident_cutting | E9: 1 | F9: 1 | G9: 65_66 | H9: 3 | I9: 7 | J9: 6.993532 | K9: 80.748217
A10: cutting | C10: =TRUE() -> TRUE | D10: incident_cutting | E10: 1 | F10: 2 | G10: 70_68 | H10: 1 | I10: 8 | J10: 7.03809 | K10: 80.8663
A11: cutting | C11: =FALSE() -> FALSE | D11: incident_cutting | E11: 1 | F11: 2 | G11: 66_70 | H11: 4 | I11: 9 | J11: 7.099661 | K11: 80.755744
A12: cutting | C12: =FALSE() -> FALSE | D12: incident_cutting | E12: 1 | F12: 1 | G12: 64_62 | H12: 2 | I12: 10 | J12: 6.890737 | K12: 80.722544
A13: cutting | C13: =FALSE() -> FALSE | D13: incident_cutting | E13: 1 | F13: 2 | G13: 65_62 | H13: 1 | I13: 11 | J13: 6.889524 | K13: 80.736845
A14: cutting | C14: =FALSE() -> FALSE | D14: incident_cutting | E14: 1 | F14: 1 | G14: 64_62 | H14: 2 | I14: 12 | J14: 6.895791 | K14: 80.724452
A15: cutting | C15: =FALSE() -> FALSE | D15: incident_cutting | E15: 1 | F15: 1 | G15: 65_66 | H15: 3 | I15: 13 | J15: 6.993532 | K15: 80.748217
A16: cutting | C16: =TRUE() -> TRUE | D16: incident_cutting | E16: 1 | F16: 1 | G16: 63_67 | H16: 4 | I16: 14 | J16: 7.03055 | K16: 80.682458
A17: cutting | C17: =FALSE() -> FALSE | D17: incident_cutting | E17: 1 | F17: 2 | G17: 67_70 | H17: 4 | I17: 15 | J17: 7.1161423 | K17: 80.791955
A18: cutting | C18: =TRUE() -> TRUE | D18: incident_cutting | E18: 1 | F18: 1 | G18: 61_66 | H18: 2 | I18: 16 | J18: 7.001066 | K18: 80.642789
A19: cutting | C19: =FALSE() -> FALSE | D19: incident_cutting | E19: 1 | F19: 3 | G19: 67_69 | H19: 4 | I19: 17 | J19: 7.0703186 | K19: 80.803366
A20: cutting | C20: =FALSE() -> FALSE | D20: incident_cutting | E20: 1 | F20: 1 | G20: 65_66 | H20: 3 | I20: 18 | J20: 7.0000154 | K20: 80.743909
A21: cutting | C21: =FALSE() -> FALSE | D21: incident_cutting | E21: 1 | F21: 2 | G21: 66_64 | H21: 2 | I21: 19 | J21: 6.9426477 | K21: 80.772136
A22: cutting | C22: =FALSE() -> FALSE | D22: incident_cutting | E22: 1 | F22: 1 | G22: 67_65 | H22: 4 | I22: 20 | J22: 6.967873 | K22: 80.783696
A23: cutting | C23: =FALSE() -> FALSE | D23: incident_cutting | E23: 1 | F23: 1 | G23: 67_64 | H23: 0 | I23: 21 | J23: 6.93816 | K23: 80.800615
A24: cutting | C24: =FALSE() -> FALSE | D24: incident_cutting | E24: 1 | F24: 1 | G24: 67_65 | H24: 4 | I24: 22 | J24: 6.967873 | K24: 80.783696
A25: cutting | C25: =FALSE() -> FALSE | D25: incident_cutting | E25: 1 | F25: 1 | G25: 65_66 | H25: 3 | I25: 23 | J25: 7.0000154 | K25: 80.743909
A26: cutting | C26: =FALSE() -> FALSE | D26: incident_cutting | E26: 1 | F26: 2 | G26: 66_64 | H26: 2 | I26: 24 | J26: 6.9426477 | K26: 80.772136
A27: cutting | C27: =FALSE() -> FALSE | D27: incident_cutting | E27: 1 | F27: 1 | G27: 67_64 | H27: 0 | I27: 25 | J27: 6.93816 | K27: 80.800615
A28: cutting | C28: =FALSE() -> FALSE | D28: incident_cutting | E28: 1 | F28: 2 | G28: 68_66 | H28: 1 | I28: 26 | J28: 6.993731 | K28: 80.818193
A29: cutting | C29: =FALSE() -> FALSE | D29: incident_cutting | E29: 1 | F29: 4 | G29: 66_69 | H29: 4 | I29: 27 | J29: 7.082207 | K29: 80.77917
A30: cutting | C30: =FALSE() -> FALSE | D30: incident_cutting | E30: 1 | F30: 3 | G30: 64_64 | H30: 4 | I30: 28 | J30: 6.9329808 | K30: 80.715098
A31: cutting | C31: =FALSE() -> FALSE | D31: incident_cutting | E31: 1 | F31: 2 | G31: 65_63 | H31: 4 | I31: 29 | J31: 6.914744 | K31: 80.750308
A32: cutting | C32: =TRUE() -> TRUE | D32: incident_cutting | E32: 1 | F32: 2 | G32: 58_68 | H32: 0 | I32: 30 | J32: 7.0580369 | K32: 80.560919
A33: cutting | C33: =TRUE() -> TRUE | D33: incident_cutting | E33: 1 | F33: 1 | G33: 62_67 | H33: 1 | I33: 31 | J33: 7.0331616 | K33: 80.649056
A34: cutting | C34: =FALSE() -> FALSE | D34: incident_cutting | E34: 1 | F34: 2 | G34: 65_71 | H34: 1 | I34: 32 | J34: 7.1371226 | K34: 80.732706
A35: cutting | C35: =FALSE() -> FALSE | D35: incident_cutting | E35: 1 | F35: 2 | G35: 65_71 | H35: 1 | I35: 33 | J35: 7.1376413 | K35: 80.731908
A36: cutting | C36: =FALSE() -> FALSE | D36: incident_cutting | E36: 1 | F36: 2 | G36: 65_71 | H36: 1 | I36: 34 | J36: 7.1371637 | K36: 80.732505
A37: cutting | C37: =FALSE() -> FALSE | D37: incident_cutting | E37: 1 | F37: 2 | G37: 64_72 | H37: 0 | I37: 35 | J37: 7.1476691 | K37: 80.727917
A38: cutting | C38: =FALSE() -> FALSE | D38: incident_cutting | E38: 1 | F38: 3 | G38: 66_70 | H38: 4 | I38: 36 | J38: 7.1127436 | K38: 80.778504
A39: cutting | C39: =FALSE() -> FALSE | D39: incident_cutting | E39: 1 | F39: 3 | G39: 67_69 | H39: 4 | I39: 37 | J39: 7.0892834 | K39: 80.795727
A40: cutting | C40: =FALSE() -> FALSE | D40: incident_cutting | E40: 1 | F40: 1 | G40: 67_72 | H40: 3 | I40: 38 | J40: 7.1563189 | K40: 80.791008
...

Sheet Dithawa_Inspections
A1: Risk_Level | B1: HR_Priorit | C1: Const_Type | D1: Disast_Nat | E1: Damage_Lvl | F1: DSD | G1: GND_Name | H1: Total_Risk | I1: insp_date | J1: event_date | K1: lon | L1: lat
A2: HR1 | B2: HR1 | C2: House / නිවාස | D2: Slope failures / බැවුම් අස්ථාවරවීම් | E2: Fully / පුර්ණහානි | F2: වලපනේ ප්රා.ලේ.කො | G2: මහඌව / කන්දේගම | H2: 13 | I2: 46035 | J2: 45988 | K2: 80.863913 | L2: 7.081365
A3: HR1 | B3: HR1 | C3: House / නිවාස | D3: Other / වෙනත් (වෙනත් කරුණු යටතේ සදහන් කරන්න) | E3: Fully / පුර්ණහානි | F3: නොර්වුඩ් ප්රා.ලේ.කො | G3: මහනෙලු | H3: 2 | K3: 80.61276 | L3: 6.809881
A4: HR1 | B4: HR1 | C4: House / නිවාස | D4: Landslide / නායයෑම් | E4: Fully / පුර්ණහානි | F4: හඟුරන්කෙත ප්රා.ලේ.කො | G4: හෝප්වත්ත | H4: 23 | I4: 46001 | J4: 45989 | K4: 80.71235 | L4: 7.127314
A5: HR1 | B5: HR1 | C5: House / නිවාස | D5: Landslide / නායයෑම් | E5: Fully / පුර්ණහානි | F5: කොත්මලේ බටහිර ප්රා.ලේ.කො | G5: රන්වන්තලාව | H5: 28 | I5: 46010 | J5: 45988 | K5: 80.624561 | L5: 7.06431
A6: HR1 | B6: HR1 | C6: House / නිවාස | D6: Slope failures / බැවුම් අස්ථාවරවීම් | E6: Fully / පුර්ණහානි | F6: වලපනේ ප්රා.ලේ.කො | G6: මුලහල්කැලේ | H6: 2 | I6: 46037 | J6: 45988 | K6: 80.856035 | L6: 7.097578
A7: HR1 | B7: HR1 | C7: House / නිවාස | D7: Landslide / නායයෑම් | E7: Fully / පුර්ණහානි | F7: හඟුරන්කෙත ප්රා.ලේ.කො | G7: කොස්ගහදෙබල | H7: 8 | K7: 80.748873 | L7: 7.155314
A8: HR1 | B8: HR1 | C8: House / නිවාස | D8: Landslide / නායයෑම් | E8: Fully / පුර්ණහානි | F8: කොත්මලේ නැගෙනහිර ප්රා.ලේ.කො | G8: රම්බොඩ සහ රම්බොඩගම | H8: 48 | I8: 46006 | J8: 45988 | K8: 80.694468 | L8: 7.066715
A9: HR1 | B9: HR1 | C9: House / නිවාස | D9: Slope failures / බැවුම් අස්ථාවරවීම් | E9: Fully / පුර්ණහානි | F9: හඟුරන්කෙත ප්රා.ලේ.කො | G9: රත්මැටිය | H9: 6 | I9: 46092 | K9: 80.776983 | L9: 7.146769
A10: HR1 | B10: HR1 | C10: House / නිවාස | D10: Landslide / නායයෑම් | E10: Fully / පුර්ණහානි | F10: කොත්මලේ බටහිර ප්රා.ලේ.කො | G10: හුණුගල්ඔය | H10: 2 | I10: 45999 | J10: 45989 | K10: 80.593306 | L10: 7.038561
A11: HR1 | B11: HR1 | C11: House / නිවාස | D11: Landslide / නායයෑම් | E11: Fully / පුර්ණහානි | F11: කොත්මලේ නැගෙනහිර ප්රා.ලේ.කො | G11: හෙල්බොඩ | H11: 37 | I11: 46008 | J11: 45988 | K11: 80.670548 | L11: 7.087255
A12: HR1 | B12: HR1 | C12: House / නිවාස | D12: Rock fall / ගල් පෙරලීම් | E12: Fully / පුර්ණහානි | F12: නිල්දණ්ඩහින්න ප්රා.ලේ.කො | G12: අඹලියද්ද | H12: 3 | K12: 80.902085 | L12: 7.019946
A13: HR1 | B13: HR1 | C13: House / නිවාස | D13: Landslide / නායයෑම් | E13: Fully / පුර්ණහානි | F13: වලපනේ ප්රා.ලේ.කො | G13: ලදුපිට | H13: 37 | K13: 80.8063 | L13: 7.101138
A14: HR1 | B14: HR1 | C14: House / නිවාස | D14: Landslide / නායයෑම් | E14: Fully / පුර්ණහානි | F14: කොත්මලේ නැගෙනහිර ප්රා.ලේ.කො | G14: නියම්ගන්දොර | H14: 18 | I14: 46005 | J14: 45988 | K14: 80.689286 | L14: 7.005897
A15: HR1 | B15: HR1 | C15: House / නිවාස | D15: Slope failures / බැවුම් අස්ථාවරවීම් | E15: Fully / පුර්ණහානි | F15: කොත්මලේ නැගෙනහිර ප්රා.ලේ.කො | G15: පලාගොල්ල | H15: 4 | I15: 46004 | J15: 45988 | K15: 80.707023 | L15: 7.04909
A16: HR1 | B16: HR1 | C16: House / නිවාස | D16: Slope failures / බැවුම් අස්ථාවරවීම් | E16: Fully / පුර්ණහානි | F16: කොත්මලේ නැගෙනහිර ප්රා.ලේ.කො | G16: රම්බොඩ | H16: 8 | I16: 46002 | J16: 45988 | K16: 80.68263 | L16: 7.071
A17: HR1 | B17: HR1 | C17: House / නිවාස | D17: Landslide / නායයෑම් | E17: Fully / පුර්ණහානි | F17: කොත්මලේ නැගෙනහිර ප්රා.ලේ.කො | G17: දෙලුම්තලාමඩ | H17: 20 | I17: 46007 | J17: 45988 | K17: 80.669145 | L17: 7.076513
A18: HR1 | B18: HR1 | C18: House / නිවාස | D18: Landslide / නායයෑම් | E18: Fully / පුර්ණහානි | F18: කොත්මලේ නැගෙනහිර ප්රා.ලේ.කො | G18: මැදකන්ද | H18: 57 | I18: 46017 | J18: 45988 | K18: 80.666355 | L18: 7.034552
A19: HR1 | B19: HR1 | C19: House / නිවාස | D19: Landslide / නායයෑම් | E19: Fully / පුර්ණහානි | F19: කොත්මලේ නැගෙනහිර ප්රා.ලේ.කො | G19: කරගස්තලාව | H19: 21 | I19: 46013 | J19: 45988 | K19: 80.695983 | L19: 7.092329
A20: HR1 | B20: HR1 | C20: House / නිවාස | D20: Slope failures / බැවුම් අස්ථාවරවීම් | E20: Fully / පුර්ණහානි | F20: කොත්මලේ නැගෙනහිර ප්රා.ලේ.කො | G20: කරගස්තලාව | H20: 6 | K20: 80.678825 | L20: 7.074155
A21: HR1 | B21: HR1 | C21: House / නිවාස | D21: Slope failures / බැවුම් අස්ථාවරවීම් | E21: Fully / පුර්ණහානි | F21: කොත්මලේ නැගෙනහිර ප්රා.ලේ.කො | G21: පලාගොල්ල | H21: 25 | I21: 46017 | J21: 45988 | K21: 80.706632 | L21: 7.034955
A22: HR1 | B22: HR1 | C22: House / නිවාස | D22: Slope failures / බැවුම් අස්ථාවරවීම් | E22: Fully / පුර්ණහානි | F22: කොත්මලේ නැගෙනහිර ප්රා.ලේ.කො | G22: සංගිලිපාලම | H22: 4 | I22: 46021 | J22: 45988 | K22: 80.679273 | L22: 7.062111
A23: HR1 | B23: HR1 | C23: House / නිවාස | D23: Landslide / නායයෑම් | E23: Fully / පුර්ණහානි | F23: කොත්මලේ බටහිර ප්රා.ලේ.කො | G23: උතුරු කොටගේපිටිය | H23: 31 | I23: 46041 | J23: 45988 | K23: 80.612438 | L23: 7.075382
A24: HR1 | B24: HR1 | C24: House / නිවාස | D24: Landslide / නායයෑම් | E24: Fully / පුර්ණහානි | F24: වලපනේ ප්රා.ලේ.කො | G24: අලකොළවැව | H24: 18 | I24: 46030 | K24: 80.805968 | L24: 7.075229
A25: HR1 | B25: HR1 | C25: House / නිවාස | D25: Landslide / නායයෑම් | E25: Fully / පුර්ණහානි | F25: කොත්මලේ නැගෙනහිර ප්රා.ලේ.කො | G25: උතුරු පූඩළුඔය | H25: 11 | I25: 46011 | J25: 45988 | K25: 80.682082 | L25: 7.015362
A26: HR1 | B26: HR1 | C26: House / නිවාස | D26: Slope failures / බැවුම් අස්ථාවරවීම් | E26: Fully / පුර්ණහානි | F26: කොත්මලේ බටහිර ප්රා.ලේ.කො | G26: රොජසන්ගම උතුර සහ රොජසන්ගම දකුණ | H26: 8 | J26: 45988 | K26: 80.62928 | L26: 7.04201
A27: HR1 | B27: HR1 | C27: House / නිවාස | D27: Slope failures / බැවුම් අස්ථාවරවීම් | E27: Fully / පුර්ණහානි | F27: අඹගමුව ප්රා.ලේ.කො | G27: කලුගල | H27: 1 | J27: 45987 | K27: 80.439913 | L27: 6.985931
A28: HR1 | B28: HR1 | C28: House / නිවාස | D28: Slope failures / බැවුම් අස්ථාවරවීම් | E28: Fully / පුර්ණහානි | F28: කොත්මලේ බටහිර ප්රා.ලේ.කො | G28: රුවන්පුර | H28: 1 | K28: 80.570912 | L28: 7.052456
A29: HR1 | B29: HR1 | C29: House / නිවාස | D29: Slope failures / බැවුම් අස්ථාවරවීම් | E29: Fully / පුර්ණහානි | F29: කොත්මලේ බටහිර ප්රා.ලේ.කො | G29: රුවන්පුර | H29: 1 | J29: 45988 | K29: 80.561161 | L29: 7.057912
A30: HR1 | B30: HR1 | C30: House / නිවාස | D30: Slope failures / බැවුම් අස්ථාවරවීම් | E30: Fully / පුර්ණහානි | F30: හඟුරන්කෙත ප්රා.ලේ.කො | G30: මාකෙම්පේ | H30: 10 | K30: 80.759173 | L30: 7.141525
A31: HR1 | B31: HR1 | C31: House / නිවාස | D31: Slope failures / බැවුම් අස්ථාවරවීම් | E31: Fully / පුර්ණහානි | F31: අඹගමුව ප්රා.ලේ.කො | G31: පිටවල | H31: 5 | K31: 80.452825 | L31: 7.002022
A32: HR1 | B32: HR1 | C32: House / නිවාස | D32: Slope failures / බැවුම් අස්ථාවරවීම් | E32: Fully / පුර්ණහානි | F32: අඹගමුව ප්රා.ලේ.කො | G32: කෙහෙල්අරාව | H32: 1 | K32: 80.475436 | L32: 6.953582
A33: HR1 | B33: HR1 | C33: House / නිවාස | D33: Slope failures / බැවුම් අස්ථාවරවීම් | E33: Fully / පුර්ණහානි | F33: හඟුරන්කෙත ප්රා.ලේ.කො | G33: ඇදිරිබැද්ද | H33: 1 | K33: 80.830361 | L33: 7.183606
A34: HR1 | B34: HR1 | C34: House / නිවාස | D34: Landslide / නායයෑම් | E34: Fully / පුර්ණහානි | F34: හඟුරන්කෙත ප්රා.ලේ.කො | G34: රුක්වුඩ් | H34: 12 | K34: 80.779809 | L34: 7.110902
A35: HR1 | B35: HR1 | C35: House / නිවාස | D35: Landslide / නායයෑම් | E35: Fully / පුර්ණහානි | F35: මතුරට ප්රා.ලේ.කො | G35: කඩදොර | H35: 2 | I35: 46012 | J35: 45988 | K35: 80.770766 | L35: 7.055598
A36: HR1 | B36: HR1 | C36: House / නිවාස | D36: Other / වෙනත් (වෙනත් කරුණු යටතේ සදහන් කරන්න) | E36: Fully / පුර්ණහානි | F36: කොත්මලේ නැගෙනහිර ප්රා.ලේ.කො | G36: මැදකන්ද | H36: 12 | I36: 46011 | J36: 45989 | K36: 80.66385 | L36: 7.026146
A37: HR1 | B37: HR1 | C37: House / නිවාස | D37: Slope failures / බැවුම් අස්ථාවරවීම් | E37: Fully / පුර්ණහානි | F37: හඟුරන්කෙත ප්රා.ලේ.කො | G37: රිකිල්ලගස්කඩ | H37: 1 | K37: 80.78088 | L37: 7.149365
A38: HR1 | B38: HR1 | C38: House / නිවාස | D38: Slope failures / බැවුම් අස්ථාවරවීම් | E38: Fully / පුර්ණහානි | F38: මතුරට ප්රා.ලේ.කො | G38: මොරගොල්ල | H38: 19 | I38: 46000 | J38: 45989 | K38: 80.816808 | L38: 7.149378
A39: HR1 | B39: HR1 | C39: House / නිවාස | D39: Landslide / නායයෑම් | E39: Fully / පුර්ණහානි | F39: මතුරට ප්රා.ලේ.කො | G39: ගෝනකැලේ | H39: 4 | I39: 46003 | J39: 45988 | K39: 80.81132 | L39: 7.05649
A40: HR1 | B40: HR1 | C40: House / නිවාස | D40: Other / වෙනත් (වෙනත් කරුණු යටතේ සදහන් කරන්න) | E40: Fully / පුර්ණහානි | F40: මතුරට ප්රා.ලේ.කො | G40: මේරිගෝල්ඩ් | H40: 3 | I40: 46003 | J40: 45988 | K40: 80.813047 | L40: 7.066025
...

Sheet Footprints
A1: Name | B1: Layer_Name | C1: Source_KMZ | D1: lon | E1: lat | F1: area_ha
A2: 13 | B2: LS_Dithawa | C2: LS_Dithawa.kmz | D2: 80.727271 | E2: 6.942392 | F2: 0.632
A3: 14 | B3: LS_Dithawa | C3: LS_Dithawa.kmz | D3: 80.740257 | E3: 6.9495 | F3: 0.673
A4: 15 | B4: LS_Dithawa | C4: LS_Dithawa.kmz | D4: 80.751274 | E4: 7.020868 | F4: 0.688
A5: 16 | B5: LS_Dithawa | C5: LS_Dithawa.kmz | D5: 80.750438 | E5: 7.029306 | F5: 0.994
A6: 17 | B6: LS_Dithawa | C6: LS_Dithawa.kmz | D6: 80.767096 | E6: 7.039708 | F6: 1.1
A7: 18 | B7: LS_Dithawa | C7: LS_Dithawa.kmz | D7: 80.743138 | E7: 7.034211 | F7: 0.79
A8: 19 | B8: LS_Dithawa | C8: LS_Dithawa.kmz | D8: 80.680373 | E8: 6.971618 | F8: 1.25
A9: 20 | B9: LS_Dithawa | C9: LS_Dithawa.kmz | D9: 80.684866 | E9: 6.966988 | F9: 0.504
A10: 21 | B10: LS_Dithawa | C10: LS_Dithawa.kmz | D10: 80.68115 | E10: 6.966517 | F10: 0.515
A11: 22 | B11: LS_Dithawa | C11: LS_Dithawa.kmz | D11: 80.691033 | E11: 6.966824 | F11: 0.659
A12: 23 | B12: LS_Dithawa | C12: LS_Dithawa.kmz | D12: 80.684055 | E12: 7.010625 | F12: 0.503
A13: 24 | B13: LS_Dithawa | C13: LS_Dithawa.kmz | D13: 80.68698 | E13: 7.012782 | F13: 0.548
... A268: NE26 | B268: NUWARA_ELIYA | C268: Nuwaraeliya_District/NUWARA_ELIYA_1.kmz | D268: 80.817078 | E268: 6.929901 | F268: 0.331

Sheet Rain_Stations
A1: type | B1: name | C1: station_id | D1: district | E1: lon | F1: lat | G1: elevation_m
A2: Rain gauge (daily/monthly) | B2: BANDARAWELA-IRRIGATION | C2: 01BD0036 | D2: BADULLA | E2: 80.98 | F2: 6.83
A3: Rain gauge (daily/monthly) | B3: DYRABBA ESTATE | C3: 01BD0102 | D3: BADULLA | E3: 80.93 | F3: 6.88
A4: Rain gauge (daily/monthly) | B4: KANDAKETIYA | C4: 01BD0207 | D4: BADULLA | E4: 81.02 | F4: 7.17
A5: Rain gauge (daily/monthly) | B5: KIRKLEES ESTATE | C5: 01BD0247 | D5: BADULLA | E5: 80.93 | F5: 6.98
A6: Rain gauge (daily/monthly) | B6: LEDGERWATTE ESTATE | C6: 01BD0271 | D6: BADULLA | E6: 81.02 | F6: 7.03
A7: Rain gauge (daily/monthly) | B7: LOWER SPRING VALLEY | C7: 01BD0277 | D7: BADULLA | E7: 81.1 | F7: 6.92
A8: Rain gauge (daily/monthly) | B8: BOGAHAMADITTA | C8: 01BD048B | D8: BADULLA | E8: 80.9 | F8: 6.97
A9: Rain gauge (daily/monthly) | B9: WEWESSA ESTATE | C9: 01BD0545 | D9: BADULLA | E9: 81.1 | F9: 6.9667
A10: Rain gauge (daily/monthly) | B10: DIYATALAWA-SURVEY CAMP | C10: 01BD093A | D10: BADULLA | E10: 80.959061 | F10: 6.816146
A11: Rain gauge (daily/monthly) | B11: HILPANKANDURA ESTATE | C11: 01BD159B | D11: BADULLA | E11: 80.9 | F11: 6.88
A12: Rain gauge (daily/monthly) | B12: MAPAKADAWEWA | C12: 01BD310A | D12: BADULLA | E12: 81.03 | F12: 7.27
A13: Rain gauge (daily/monthly) | B13: RANTEMBE | C13: 01BD317Q | D13: BADULLA | E13: 80.93 | F13: 7.2
... A93: Rain gauge (daily/monthly) | B93: WATAWALA MOUNT JEAN | C93: 01NE534B | D93: NUWARA ELIA | E93: 80.52 | F93: 6.95
A94: Agromet | B94: KOTHMALE | C94: 01AG12 | D94: KANDY | E94: 80.58 | F94: 7.08 | G94: 716
A95: Agromet | B95: KUNDASALE | C95: 01AG14 | D95: KANDY | E95: 80.68 | F95: 7.27 | G95: 492
A96: Agromet | B96: GANNORUWA | C96: 01AG21 | D96: KANDY | E96: 80.6 | F96: 7.25 | G96: 488
A97: Agromet | B97: POLGOLLA | C97: 01AG22 | D97: KANDY | E97: 80.65 | F97: 7.32 | G97: 440
A98: Agromet | B98: RANDENIGALA | C98: 01AG23 | D98: KANDY | E98: 80.95 | F98: 7.2 | G98: 220
A99: Agromet | B99: SEETHAELIYA | C99: 01AG27 | D99: NUWARAELIYA | E99: 80.79897 | F99: 6.9517264 | G99: 1860
A100: Agromet | B100: THALAWAKELLE | C100: 01AG28 | D100: NUWARAELIYA | E100: 80.66 | F100: 6.93 | G100: 1500
A101: Agromet | B101: VICTORIA | C101: 01AG31 | D101: KANDY | E101: 80.83103 | F101: 7.1795627 | G101: 488
A102: Agromet | B102: BANDARAWELA | C102: 143476 | D102: BADULLA | E102: 80.986276 | F102: 6.8308765 | G102: 1225
A103: Synoptic met | B103: BANDARAWELA | C103: 43476 | E103: 80.98626 | F103: 6.8309042 | G103: 1225
A104: Synoptic met | B104: KATUGASTOTA | C104: 43444 | E104: 80.626417 | F104: 7.334448 | G104: 417
A105: Synoptic met | B105: NUWARA ELIYA | C105: 43473 | E105: 80.779152 | F105: 6.9695314 | G105: 1894
A106: Synoptic met | B106: BADULLA | C106: 43479 | E106: 81.048616 | F106: 6.9833652 | G106: 670
